Workbook
Name Slicer_Representative: #N/A

Sheet Data
B1: Call Centre Data
B3: Call number | C3: Customer ID | D3: Duration | E3: Representative | F3: Date of Call | G3: Purchase Amount | H3: Satisfaction Rating | I3: FY | J3: Day of week | K3: Duration Bucket | L3: Rating rounded | M3: Month | Q3: Customer ID | R3: Gedner | S3: Age | T3: City
B4: Call_7271 | C4: C0003 | D4: 116 | E4: R05 | F4: 44927 | G4: 128 | H4: 4.9 | I4: =IF(MONTH(calls[[#This Row],[Date of Call]])<=6, YEAR(calls[[#This Row],[Date of Call]]), YEAR(calls[[#This Row],[Date of Call]])+1) -> 2023 | J4: =TEXT(calls[[#This Row],[Date of Call]],"DDDD") -> Sunday | K4: {=_xlfn.IFS(calls[[#This Row],[Duration]]<=10,"Under 10 mins", calls[[#This Row],[Duration]]<=30, "10 to 30 mins", calls[[#This Row],[Duration]]<=60, "30 to 60 mins", calls[[#This Row],[Duration]]<=120, "1 to 2 hours", TRUE, "More than 2 hours")} -> 1 to 2 hours | L4: =ROUND(calls[[#This Row],[Satisfaction Rating]],0) -> 5 | M4: =TEXT(calls[[#This Row],[Date of Call]],"MMMM") -> January | Q4: C0001 | R4: Male | S4: 41 | T4: Columbus
B5: Call_7272 | C5: C0004 | D5: 119 | E5: R05 | F5: 44927 | G5: 135 | H5: 2.9 | I5: =IF(MONTH(calls[[#This Row],[Date of Call]])<=6, YEAR(calls[[#This Row],[Date of Call]]), YEAR(calls[[#This Row],[Date of Call]])+1) -> 2023 | J5: =TEXT(calls[[#This Row],[Date of Call]],"DDDD") -> Sunday | K5: {=_xlfn.IFS(calls[[#This Row],[Duration]]<=10,"Under 10 mins", calls[[#This Row],[Duration]]<=30, "10 to 30 mins", calls[[#This Row],[Duration]]<=60, "30 to 60 mins", calls[[#This Row],[Duration]]<=120, "1 to 2 hours", TRUE, "More than 2 hours")} -> 1 to 2 hours | L5: =ROUND(calls[[#This Row],[Satisfaction Rating]],0) -> 3 | M5: =TEXT(calls[[#This Row],[Date of Call]],"MMMM") -> January | Q5: C0002 | R5: Male | S5: 31 | T5: Cleveland
B6: Call_7273 | C6: C0005 | D6: 68 | E6: R02 | F6: 44927 | G6: 66 | H6: 4.7 | I6: =IF(MONTH(calls[[#This Row],[Date of Call]])<=6, YEAR(calls[[#This Row],[Date of Call]]), YEAR(calls[[#This Row],[Date of Call]])+1) -> 2023 | J6: =TEXT(calls[[#This Row],[Date of Call]],"DDDD") -> Sunday | K6: {=_xlfn.IFS(calls[[#This Row],[Duration]]<=10,"Under 10 mins", calls[[#This Row],[Duration]]<=30, "10 to 30 mins", calls[[#This Row],[Duration]]<=60, "30 to 60 mins", calls[[#This Row],[Duration]]<=120, "1 to 2 hours", TRUE, "More than 2 hours")} -> 1 to 2 hours | L6: =ROUND(calls[[#This Row],[Satisfaction Rating]],0) -> 5 | M6: =TEXT(calls[[#This Row],[Date of Call]],"MMMM") -> January | Q6: C0003 | R6: Male | S6: 26 | T6: Cincinnati
B7: Call_7274 | C7: C0014 | D7: 119 | E7: R02 | F7: 44927 | G7: 22 | H7: 2.9 | I7: =IF(MONTH(calls[[#This Row],[Date of Call]])<=6, YEAR(calls[[#This Row],[Date of Call]]), YEAR(calls[[#This Row],[Date of Call]])+1) -> 2023 | J7: =TEXT(calls[[#This Row],[Date of Call]],"DDDD") -> Sunday | K7: {=_xlfn.IFS(calls[[#This Row],[Duration]]<=10,"Under 10 mins", calls[[#This Row],[Duration]]<=30, "10 to 30 mins", calls[[#This Row],[Duration]]<=60, "30 to 60 mins", calls[[#This Row],[Duration]]<=120, "1 to 2 hours", TRUE, "More than 2 hours")} -> 1 to 2 hours | L7: =ROUND(calls[[#This Row],[Satisfaction Rating]],0) -> 3 | M7: =TEXT(calls[[#This Row],[Date of Call]],"MMMM") -> January | Q7: C0004 | R7: Male | S7: 36 | T7: Cincinnati
B8: Call_7275 | C8: C0011 | D8: 128 | E8: R01 | F8: 44928 | G8: 31 | H8: 2.8 | I8: =IF(MONTH(calls[[#This Row],[Date of Call]])<=6, YEAR(calls[[#This Row],[Date of Call]]), YEAR(calls[[#This Row],[Date of Call]])+1) -> 2023 | J8: =TEXT(calls[[#This Row],[Date of Call]],"DDDD") -> Monday | K8: {=_xlfn.IFS(calls[[#This Row],[Duration]]<=10,"Under 10 mins", calls[[#This Row],[Duration]]<=30, "10 to 30 mins", calls[[#This Row],[Duration]]<=60, "30 to 60 mins", calls[[#This Row],[Duration]]<=120, "1 to 2 hours", TRUE, "More than 2 hours")} -> More than 2 hours | L8: =ROUND(calls[[#This Row],[Satisfaction Rating]],0) -> 3 | M8: =TEXT(calls[[#This Row],[Date of Call]],"MMMM") -> January | Q8: C0005 | R8: Male | S8: 37 | T8: Columbus
B9: Call_7276 | C9: C0011 | D9: 49 | E9: R02 | F9: 44929 | G9: 135 | H9: 4.8 | I9: =IF(MONTH(calls[[#This Row],[Date of Call]])<=6, YEAR(calls[[#This Row],[Date of Call]]), YEAR(calls[[#This Row],[Date of Call]])+1) -> 2023 | J9: =TEXT(calls[[#This Row],[Date of Call]],"DDDD") -> Tuesday | K9: {=_xlfn.IFS(calls[[#This Row],[Duration]]<=10,"Under 10 mins", calls[[#This Row],[Duration]]<=30, "10 to 30 mins", calls[[#This Row],[Duration]]<=60, "30 to 60 mins", calls[[#This Row],[Duration]]<=120, "1 to 2 hours", TRUE, "More than 2 hours")} -> 30 to 60 mins | L9: =ROUND(calls[[#This Row],[Satisfaction Rating]],0) -> 5 | M9: =TEXT(calls[[#This Row],[Date of Call]],"MMMM") -> January | Q9: C0006 | R9: Male | S9: 23 | T9: Columbus
B10: Call_7277 | C10: C0007 | D10: 84 | E10: R05 | F10: 44929 | G10: 60 | H10: 4.7 | I10: =IF(MONTH(calls[[#This Row],[Date of Call]])<=6, YEAR(calls[[#This Row],[Date of Call]]), YEAR(calls[[#This Row],[Date of Call]])+1) -> 2023 | J10: =TEXT(calls[[#This Row],[Date of Call]],"DDDD") -> Tuesday | K10: {=_xlfn.IFS(calls[[#This Row],[Duration]]<=10,"Under 10 mins", calls[[#This Row],[Duration]]<=30, "10 to 30 mins", calls[[#This Row],[Duration]]<=60, "30 to 60 mins", calls[[#This Row],[Duration]]<=120, "1 to 2 hours", TRUE, "More than 2 hours")} -> 1 to 2 hours | L10: =ROUND(calls[[#This Row],[Satisfaction Rating]],0) -> 5 | M10: =TEXT(calls[[#This Row],[Date of Call]],"MMMM") -> January | Q10: C0007 | R10: Female | S10: 22 | T10: Cleveland
B11: Call_7278 | C11: C0003 | D11: 103 | E11: R04 | F11: 44929 | G11: 148 | H11: 4.4 | I11: =IF(MONTH(calls[[#This Row],[Date of Call]])<=6, YEAR(calls[[#This Row],[Date of Call]]), YEAR(calls[[#This Row],[Date of Call]])+1) -> 2023 | J11: =TEXT(calls[[#This Row],[Date of Call]],"DDDD") -> Tuesday | K11: {=_xlfn.IFS(calls[[#This Row],[Duration]]<=10,"Under 10 mins", calls[[#This Row],[Duration]]<=30, "10 to 30 mins", calls[[#This Row],[Duration]]<=60, "30 to 60 mins", calls[[#This Row],[Duration]]<=120, "1 to 2 hours", TRUE, "More than 2 hours")} -> 1 to 2 hours | L11: =ROUND(calls[[#This Row],[Satisfaction Rating]],0) -> 4 | M11: =TEXT(calls[[#This Row],[Date of Call]],"MMMM") -> January | Q11: C0008 | R11: Female | S11: 42 | T11: Cleveland
B12: Call_7279 | C12: C0005 | D12: 31 | E12: R02 | F12: 44929 | G12: 135 | H12: 3.6 | I12: =IF(MONTH(calls[[#This Row],[Date of Call]])<=6, YEAR(calls[[#This Row],[Date of Call]]), YEAR(calls[[#This Row],[Date of Call]])+1) -> 2023 | J12: =TEXT(calls[[#This Row],[Date of Call]],"DDDD") -> Tuesday | K12: {=_xlfn.IFS(calls[[#This Row],[Duration]]<=10,"Under 10 mins", calls[[#This Row],[Duration]]<=30, "10 to 30 mins", calls[[#This Row],[Duration]]<=60, "30 to 60 mins", calls[[#This Row],[Duration]]<=120, "1 to 2 hours", TRUE, "More than 2 hours")} -> 30 to 60 mins | L12: =ROUND(calls[[#This Row],[Satisfaction Rating]],0) -> 4 | M12: =TEXT(calls[[#This Row],[Date of Call]],"MMMM") -> January | Q12: C0009 | R12: Female | S12: 25 | T12: Columbus
B13: Call_7280 | C13: C0010 | D13: 44 | E13: R03 | F13: 44929 | G13: 105 | H13: 2.9 | I13: =IF(MONTH(calls[[#This Row],[Date of Call]])<=6, YEAR(calls[[#This Row],[Date of Call]]), YEAR(calls[[#This Row],[Date of Call]])+1) -> 2023 | J13: =TEXT(calls[[#This Row],[Date of Call]],"DDDD") -> Tuesday | K13: {=_xlfn.IFS(calls[[#This Row],[Duration]]<=10,"Under 10 mins", calls[[#This Row],[Duration]]<=30, "10 to 30 mins", calls[[#This Row],[Duration]]<=60, "30 to 60 mins", calls[[#This Row],[Duration]]<=120, "1 to 2 hours", TRUE, "More than 2 hours")} -> 30 to 60 mins | L13: =ROUND(calls[[#This Row],[Satisfaction Rating]],0) -> 3 | M13: =TEXT(calls[[#This Row],[Date of Call]],"MMMM") -> January | Q13: C0010 | R13: Female | S13: 30 | T13: Cleveland
B14: Call_7281 | C14: C0011 | D14: 102 | E14: R02 | F14: 44929 | G14: 69 | H14: 4.9 | I14: =IF(MONTH(calls[[#This Row],[Date of Call]])<=6, YEAR(calls[[#This Row],[Date of Call]]), YEAR(calls[[#This Row],[Date of Call]])+1) -> 2023 | J14: =TEXT(calls[[#This Row],[Date of Call]],"DDDD") -> Tuesday | K14: {=_xlfn.IFS(calls[[#This Row],[Duration]]<=10,"Under 10 mins", calls[[#This Row],[Duration]]<=30, "10 to 30 mins", calls[[#This Row],[Duration]]<=60, "30 to 60 mins", calls[[#This Row],[Duration]]<=120, "1 to 2 hours", TRUE, "More than 2 hours")} -> 1 to 2 hours | L14: =ROUND(calls[[#This Row],[Satisfaction Rating]],0) -> 5 | M14: =TEXT(calls[[#This Row],[Date of Call]],"MMMM") -> January | Q14: C0011 | R14: Female | S14: 30 | T14: Cincinnati
B15: Call_7282 | C15: C0013 | D15: 135 | E15: R05 | F15: 44929 | G15: 46 | H15: 3.4 | I15: =IF(MONTH(calls[[#This Row],[Date of Call]])<=6, YEAR(calls[[#This Row],[Date of Call]]), YEAR(calls[[#This Row],[Date of Call]])+1) -> 2023 | J15: =TEXT(calls[[#This Row],[Date of Call]],"DDDD") -> Tuesday | K15: {=_xlfn.IFS(calls[[#This Row],[Duration]]<=10,"Under 10 mins", calls[[#This Row],[Duration]]<=30, "10 to 30 mins", calls[[#This Row],[Duration]]<=60, "30 to 60 mins", calls[[#This Row],[Duration]]<=120, "1 to 2 hours", TRUE, "More than 2 hours")} -> More than 2 hours | L15: =ROUND(calls[[#This Row],[Satisfaction Rating]],0) -> 3 | M15: =TEXT(calls[[#This Row],[Date of Call]],"MMMM") -> January | Q15: C0012 | R15: Female | S15: 28 | T15: Cincinnati
... B18: Call_7285 | C18: C0013 | D18: 48 | E18: R01 | F18: 44930 | G18: 68 | H18: 4.9 | I18: =IF(MONTH(calls[[#This Row],[Date of Call]])<=6, YEAR(calls[[#This Row],[Date of Call]]), YEAR(calls[[#This Row],[Date of Call]])+1) -> 2023 | J18: =TEXT(calls[[#This Row],[Date of Call]],"DDDD") -> Wednesday | K18: {=_xlfn.IFS(calls[[#This Row],[Duration]]<=10,"Under 10 mins", calls[[#This Row],[Duration]]<=30, "10 to 30 mins", calls[[#This Row],[Duration]]<=60, "30 to 60 mins", calls[[#This Row],[Duration]]<=120, "1 to 2 hours", TRUE, "More than 2 hours")} -> 30 to 60 mins | L18: =ROUND(calls[[#This Row],[Satisfaction Rating]],0) -> 5 | M18: =TEXT(calls[[#This Row],[Date of Call]],"MMMM") -> January | Q18: C0015 | R18: Female | S18: 43 | T18: Cleveland
B19: Call_7286 | C19: C0010 | D19: 176 | E19: R05 | F19: 44931 | G19: 24 | H19: 4.8 | I19: =IF(MONTH(calls[[#This Row],[Date of Call]])<=6, YEAR(calls[[#This Row],[Date of Call]]), YEAR(calls[[#This Row],[Date of Call]])+1) -> 2023 | J19: =TEXT(calls[[#This Row],[Date of Call]],"DDDD") -> Thursday | K19: {=_xlfn.IFS(calls[[#This Row],[Duration]]<=10,"Under 10 mins", calls[[#This Row],[Duration]]<=30, "10 to 30 mins", calls[[#This Row],[Duration]]<=60, "30 to 60 mins", calls[[#This Row],[Duration]]<=120, "1 to 2 hours", TRUE, "More than 2 hours")} -> More than 2 hours | L19: =ROUND(calls[[#This Row],[Satisfaction Rating]],0) -> 5 | M19: =TEXT(calls[[#This Row],[Date of Call]],"MMMM") -> January
B20: Call_7287 | C20: C0010 | D20: 99 | E20: R01 | F20: 44931 | G20: 195 | H20: 3.9 | I20: =IF(MONTH(calls[[#This Row],[Date of Call]])<=6, YEAR(calls[[#This Row],[Date of Call]]), YEAR(calls[[#This Row],[Date of Call]])+1) -> 2023 | J20: =TEXT(calls[[#This Row],[Date of Call]],"DDDD") -> Thursday | K20: {=_xlfn.IFS(calls[[#This Row],[Duration]]<=10,"Under 10 mins", calls[[#This Row],[Duration]]<=30, "10 to 30 mins", calls[[#This Row],[Duration]]<=60, "30 to 60 mins", calls[[#This Row],[Duration]]<=120, "1 to 2 hours", TRUE, "More than 2 hours")} -> 1 to 2 hours | L20: =ROUND(calls[[#This Row],[Satisfaction Rating]],0) -> 4 | M20: =TEXT(calls[[#This Row],[Date of Call]],"MMMM") -> January
B21: Call_7288 | C21: C0009 | D21: 28 | E21: R03 | F21: 44931 | G21: 28 | H21: 3.8 | I21: =IF(MONTH(calls[[#This Row],[Date of Call]])<=6, YEAR(calls[[#This Row],[Date of Call]]), YEAR(calls[[#This Row],[Date of Call]])+1) -> 2023 | J21: =TEXT(calls[[#This Row],[Date of Call]],"DDDD") -> Thursday | K21: {=_xlfn.IFS(calls[[#This Row],[Duration]]<=10,"Under 10 mins", calls[[#This Row],[Duration]]<=30, "10 to 30 mins", calls[[#This Row],[Duration]]<=60, "30 to 60 mins", calls[[#This Row],[Duration]]<=120, "1 to 2 hours", TRUE, "More than 2 hours")} -> 10 to 30 mins | L21: =ROUND(calls[[#This Row],[Satisfaction Rating]],0) -> 4 | M21: =TEXT(calls[[#This Row],[Date of Call]],"MMMM") -> January
B22: Call_7289 | C22: C0007 | D22: 54 | E22: R02 | F22: 44931 | G22: 170 | H22: 4.3 | I22: =IF(MONTH(calls[[#This Row],[Date of Call]])<=6, YEAR(calls[[#This Row],[Date of Call]]), YEAR(calls[[#This Row],[Date of Call]])+1) -> 2023 | J22: =TEXT(calls[[#This Row],[Date of Call]],"DDDD") -> Thursday | K22: {=_xlfn.IFS(calls[[#This Row],[Duration]]<=10,"Under 10 mins", calls[[#This Row],[Duration]]<=30, "10 to 30 mins", calls[[#This Row],[Duration]]<=60, "30 to 60 mins", calls[[#This Row],[Duration]]<=120, "1 to 2 hours", TRUE, "More than 2 hours")} -> 30 to 60 mins | L22: =ROUND(calls[[#This Row],[Satisfaction Rating]],0) -> 4 | M22: =TEXT(calls[[#This Row],[Date of Call]],"MMMM") -> January
B23: Call_7290 | C23: C0006 | D23: 48 | E23: R05 | F23: 44932 | G23: 30 | H23: 4.4 | I23: =IF(MONTH(calls[[#This Row],[Date of Call]])<=6, YEAR(calls[[#This Row],[Date of Call]]), YEAR(calls[[#This Row],[Date of Call]])+1) -> 2023 | J23: =TEXT(calls[[#This Row],[Date of Call]],"DDDD") -> Friday | K23: {=_xlfn.IFS(calls[[#This Row],[Duration]]<=10,"Under 10 mins", calls[[#This Row],[Duration]]<=30, "10 to 30 mins", calls[[#This Row],[Duration]]<=60, "30 to 60 mins", calls[[#This Row],[Duration]]<=120, "1 to 2 hours", TRUE, "More than 2 hours")} -> 30 to 60 mins | L23: =ROUND(calls[[#This Row],[Satisfaction Rating]],0) -> 4 | M23: =TEXT(calls[[#This Row],[Date of Call]],"MMMM") -> January
B24: Call_7291 | C24: C0004 | D24: 128 | E24: R05 | F24: 44932 | G24: 72 | H24: 5 | I24: =IF(MONTH(calls[[#This Row],[Date of Call]])<=6, YEAR(calls[[#This Row],[Date of Call]]), YEAR(calls[[#This Row],[Date of Call]])+1) -> 2023 | J24: =TEXT(calls[[#This Row],[Date of Call]],"DDDD") -> Friday | K24: {=_xlfn.IFS(calls[[#This Row],[Duration]]<=10,"Under 10 mins", calls[[#This Row],[Duration]]<=30, "10 to 30 mins", calls[[#This Row],[Duration]]<=60, "30 to 60 mins", calls[[#This Row],[Duration]]<=120, "1 to 2 hours", TRUE, "More than 2 hours")} -> More than 2 hours | L24: =ROUND(calls[[#This Row],[Satisfaction Rating]],0) -> 5 | M24: =TEXT(calls[[#This Row],[Date of Call]],"MMMM") -> January
B25: Call_7292 | C25: C0004 | D25: 38 | E25: R04 | F25: 44933 | G25: 92 | H25: 4.9 | I25: =IF(MONTH(calls[[#This Row],[Date of Call]])<=6, YEAR(calls[[#This Row],[Date of Call]]), YEAR(calls[[#This Row],[Date of Call]])+1) -> 2023 | J25: =TEXT(calls[[#This Row],[Date of Call]],"DDDD") -> Saturday | K25: {=_xlfn.IFS(calls[[#This Row],[Duration]]<=10,"Under 10 mins", calls[[#This Row],[Duration]]<=30, "10 to 30 mins", calls[[#This Row],[Duration]]<=60, "30 to 60 mins", calls[[#This Row],[Duration]]<=120, "1 to 2 hours", TRUE, "More than 2 hours")} -> 30 to 60 mins | L25: =ROUND(calls[[#This Row],[Satisfaction Rating]],0) -> 5 | M25: =TEXT(calls[[#This Row],[Date of Call]],"MMMM") -> January
B26: Call_7293 | C26: C0003 | D26: 67 | E26: R04 | F26: 44934 | G26: 165 | H26: 4.5 | I26: =IF(MONTH(calls[[#This Row],[Date of Call]])<=6, YEAR(calls[[#This Row],[Date of Call]]), YEAR(calls[[#This Row],[Date of Call]])+1) -> 2023 | J26: =TEXT(calls[[#This Row],[Date of Call]],"DDDD") -> Sunday | K26: {=_xlfn.IFS(calls[[#This Row],[Duration]]<=10,"Under 10 mins", calls[[#This Row],[Duration]]<=30, "10 to 30 mins", calls[[#This Row],[Duration]]<=60, "30 to 60 mins", calls[[#This Row],[Duration]]<=120, "1 to 2 hours", TRUE, "More than 2 hours")} -> 1 to 2 hours | L26: =ROUND(calls[[#This Row],[Satisfaction Rating]],0) -> 5 | M26: =TEXT(calls[[#This Row],[Date of Call]],"MMMM") -> January
B27: Call_7294 | C27: C0015 | D27: 58 | E27: R02 | F27: 44934 | G27: 140 | H27: 2.1 | I27: =IF(MONTH(calls[[#This Row],[Date of Call]])<=6, YEAR(calls[[#This Row],[Date of Call]]), YEAR(calls[[#This Row],[Date of Call]])+1) -> 2023 | J27: =TEXT(calls[[#This Row],[Date of Call]],"DDDD") -> Sunday | K27: {=_xlfn.IFS(calls[[#This Row],[Duration]]<=10,"Under 10 mins", calls[[#This Row],[Duration]]<=30, "10 to 30 mins", calls[[#This Row],[Duration]]<=60, "30 to 60 mins", calls[[#This Row],[Duration]]<=120, "1 to 2 hours", TRUE, "More than 2 hours")} -> 30 to 60 mins | L27: =ROUND(calls[[#This Row],[Satisfaction Rating]],0) -> 2 | M27: =TEXT(calls[[#This Row],[Date of Call]],"MMMM") -> January
B28: Call_7295 | C28: C0010 | D28: 54 | E28: R01 | F28: 44934 | G28: 111 | H28: 3.3 | I28: =IF(MONTH(calls[[#This Row],[Date of Call]])<=6, YEAR(calls[[#This Row],[Date of Call]]), YEAR(calls[[#This Row],[Date of Call]])+1) -> 2023 | J28: =TEXT(calls[[#This Row],[Date of Call]],"DDDD") -> Sunday | K28: {=_xlfn.IFS(calls[[#This Row],[Duration]]<=10,"Under 10 mins", calls[[#This Row],[Duration]]<=30, "10 to 30 mins", calls[[#This Row],[Duration]]<=60, "30 to 60 mins", calls[[#This Row],[Duration]]<=120, "1 to 2 hours", TRUE, "More than 2 hours")} -> 30 to 60 mins | L28: =ROUND(calls[[#This Row],[Satisfaction Rating]],0) -> 3 | M28: =TEXT(calls[[#This Row],[Date of Call]],"MMMM") -> January
B29: Call_7296 | C29: C0012 | D29: 28 | E29: R05 | F29: 44935 | G29: 63 | H29: 4.1 | I29: =IF(MONTH(calls[[#This Row],[Date of Call]])<=6, YEAR(calls[[#This Row],[Date of Call]]), YEAR(calls[[#This Row],[Date of Call]])+1) -> 2023 | J29: =TEXT(calls[[#This Row],[Date of Call]],"DDDD") -> Monday | K29: {=_xlfn.IFS(calls[[#This Row],[Duration]]<=10,"Under 10 mins", calls[[#This Row],[Duration]]<=30, "10 to 30 mins", calls[[#This Row],[Duration]]<=60, "30 to 60 mins", calls[[#This Row],[Duration]]<=120, "1 to 2 hours", TRUE, "More than 2 hours")} -> 10 to 30 mins | L29: =ROUND(calls[[#This Row],[Satisfaction Rating]],0) -> 4 | M29: =TEXT(calls[[#This Row],[Date of Call]],"MMMM") -> January
B30: Call_7297 | C30: C0002 | D30: 73 | E30: R05 | F30: 44935 | G30: 80 | H30: 4.2 | I30: =IF(MONTH(calls[[#This Row],[Date of Call]])<=6, YEAR(calls[[#This Row],[Date of Call]]), YEAR(calls[[#This Row],[Date of Call]])+1) -> 2023 | J30: =TEXT(calls[[#This Row],[Date of Call]],"DDDD") -> Monday | K30: {=_xlfn.IFS(calls[[#This Row],[Duration]]<=10,"Under 10 mins", calls[[#This Row],[Duration]]<=30, "10 to 30 mins", calls[[#This Row],[Duration]]<=60, "30 to 60 mins", calls[[#This Row],[Duration]]<=120, "1 to 2 hours", TRUE, "More than 2 hours")} -> 1 to 2 hours | L30: =ROUND(calls[[#This Row],[Satisfaction Rating]],0) -> 4 | M30: =TEXT(calls[[#This Row],[Date of Call]],"MMMM") -> January
... B1003: Call_8270 | C1003: C0009 | D1003: 114 | E1003: R01 | F1003: 45291 | G1003: 40 | H1003: 3.9 | I1003: =IF(MONTH(calls[[#This Row],[Date of Call]])<=6, YEAR(calls[[#This Row],[Date of Call]]), YEAR(calls[[#This Row],[Date of Call]])+1) -> 2024 | J1003: =TEXT(calls[[#This Row],[Date of Call]],"DDDD") -> Sunday | K1003: {=_xlfn.IFS(calls[[#This Row],[Duration]]<=10,"Under 10 mins", calls[[#This Row],[Duration]]<=30, "10 to 30 mins", calls[[#This Row],[Duration]]<=60, "30 to 60 mins", calls[[#This Row],[Duration]]<=120, "1 to 2 hours", TRUE, "More than 2 hours")} -> 1 to 2 hours | L1003: =ROUND(calls[[#This Row],[Satisfaction Rating]],0) -> 4 | M1003: =TEXT(calls[[#This Row],[Date of Call]],"MMMM") -> December

Sheet Pivot
A3: Call Count | B3: Total Amount | C3: Total Duration | D3: Avg Rating | E3: 5 STAR Calls
A4: 1000 | B4: 96623 | C4: 89850 | D4: 3.8854 | E4: 307
A12: Call Count | B12: Total Amount | C12: Total Duration | D12: Avg Rating | E12: 5 STAR Calls
A13: 207 | B13: 20872 | C13: 17700 | D13: 3.8589372 | E13: 60
A17: Row Labels | B17: Call Count | C17: Call Count2
A18: Jan | B18: 13 | C18: 13
A19: Feb | B19: 13 | C19: 13
A20: Mar | B20: 28 | C20: 28
A21: Apr | B21: 24 | C21: 24
A22: May | B22: 23 | C22: 23
A23: Jun | B23: 17 | C23: 17
A24: Jul | B24: 11 | C24: 11
A25: Aug | B25: 11 | C25: 11
A26: Sep | B26: 14 | C26: 14
A27: Oct | B27: 30 | C27: 30
A28: Nov | B28: 14 | C28: 14
A29: Dec | B29: 9 | C29: 9
A32: Row Labels | B32: Call Count
A33: Sunday | B33: 30
A34: Monday | B34: 34
A35: Tuesday | B35: 26
A36: Wednesday | B36: 38
A37: Thursday | B37: 27
A38: Friday | B38: 27
A39: Saturday | B39: 25
C46: rep summary
F47: Lables (only single select)
C48: %calls | D48: =GETPIVOTDATA("[Measures].[Call Count]",$A$12)/GETPIVOTDATA("[Measures].[Call Count]",$A$3) -> 0.207
C49: calls | D49: =VLOOKUP(J54,E61:G65,2,FALSE) -> 207 | F49: =IF(COUNTA(J54:J58)>1,"","% of calls:"&TEXT(D48,"0%")) -> % of calls:21%
C50: amount | D50: =VLOOKUP(J54,E61:G65,3,FALSE) -> 20872 | F50: =IF(COUNTA(J54:J58)>1,"","call rank:"&D52) -> call rank:2 | J50: selected Rep | K50: =J54 -> R03
F51: =IF(COUNTA(J54:J58)>1,"","amount rank:"&D53) -> amount rank:1
C52: calls rank | D52: =_xlfn.RANK.AVG(D49,F61:F65) -> 2
C53: amount rank | D53: =_xlfn.RANK.AVG(D50,G61:G65) -> 1 | J53: Row Labels
J54: R03
A60: Row Labels | B60: Call Count | C60: Total Amount | F60: calls | G60: amount | H60: selected call | I60: selected amt
A61: R01 | B61: 189 | C61: 18415 | E61: =A61 -> R01 | F61: =B61 -> 189 | G61: =C61 -> 18415 | H61: =IF(E61=$K$50,F61,NA()) -> #N/A | I61: =IF(E61=$K$50,G61,NA()) -> #N/A
A62: R02 | B62: 218 | C62: 20581 | E62: =A62 -> R02 | F62: =B62 -> 218 | G62: =C62 -> 20581 | H62: =IF(E62=$K$50,F62,NA()) -> #N/A | I62: =IF(E62=$K$50,G62,NA()) -> #N/A
A63: R03 | B63: 207 | C63: 20872 | E63: =A63 -> R03 | F63: =B63 -> 207 | G63: =C63 -> 20872 | H63: =IF(E63=$K$50,F63,NA()) -> 207 | I63: =IF(E63=$K$50,G63,NA()) -> 20872
A64: R04 | B64: 186 | C64: 16651 | E64: =A64 -> R04 | F64: =B64 -> 186 | G64: =C64 -> 16651 | H64: =IF(E64=$K$50,F64,NA()) -> #N/A | I64: =IF(E64=$K$50,G64,NA()) -> #N/A
A65: R05 | B65: 200 | C65: 20104 | E65: =A65 -> R05 | F65: =B65 -> 200 | G65: =C65 -> 20104 | H65: =IF(E65=$K$50,F65,NA()) -> #N/A | I65: =IF(E65=$K$50,G65,NA()) -> #N/A
...

Sheet Dashboard
P18: =Pivot!B90 -> R01 | Q18: =Pivot!C90 -> R02 | R18: =Pivot!D90 -> R03 | S18: =Pivot!E90 -> R04 | T18: =Pivot!F90 -> R05 | U18: =Pivot!G90 -> Total
O19: =Pivot!A91 -> Cincinnati | P19: =IF(Pivot!B91="","",Pivot!B91) | Q19: =IF(Pivot!C91="","",Pivot!C91) | R19: =IF(Pivot!D91="","",Pivot!D91) | S19: =IF(Pivot!E91="","",Pivot!E91) | T19: =IF(Pivot!F91="","",Pivot!F91) | U19: =IF(Pivot!G91="","",Pivot!G91)
O20: =Pivot!A92 -> C0003 | P20: =IF(Pivot!B92="","",Pivot!B92) -> 891 | Q20: =IF(Pivot!C92="","",Pivot!C92) -> 1332 | R20: =IF(Pivot!D92="","",Pivot!D92) -> 1282 | S20: =IF(Pivot!E92="","",Pivot!E92) -> 739 | T20: =IF(Pivot!F92="","",Pivot!F92) -> 560 | U20: =IF(Pivot!G92="","",Pivot!G92) -> 4804
O21: =Pivot!A93 -> C0004 | P21: =IF(Pivot!B93="","",Pivot!B93) -> 1991 | Q21: =IF(Pivot!C93="","",Pivot!C93) -> 1886 | R21: =IF(Pivot!D93="","",Pivot!D93) -> 1206 | S21: =IF(Pivot!E93="","",Pivot!E93) -> 884 | T21: =IF(Pivot!F93="","",Pivot!F93) -> 1722 | U21: =IF(Pivot!G93="","",Pivot!G93) -> 7689
O22: =Pivot!A94 -> C0011 | P22: =IF(Pivot!B94="","",Pivot!B94) -> 1163 | Q22: =IF(Pivot!C94="","",Pivot!C94) -> 1180 | R22: =IF(Pivot!D94="","",Pivot!D94) -> 1616 | S22: =IF(Pivot!E94="","",Pivot!E94) -> 1043 | T22: =IF(Pivot!F94="","",Pivot!F94) -> 1747 | U22: =IF(Pivot!G94="","",Pivot!G94) -> 6749
O23: =Pivot!A95 -> C0012 | P23: =IF(Pivot!B95="","",Pivot!B95) -> 1438 | Q23: =IF(Pivot!C95="","",Pivot!C95) -> 1616 | R23: =IF(Pivot!D95="","",Pivot!D95) -> 866 | S23: =IF(Pivot!E95="","",Pivot!E95) -> 829 | T23: =IF(Pivot!F95="","",Pivot!F95) -> 2070 | U23: =IF(Pivot!G95="","",Pivot!G95) -> 6819
O24: =Pivot!A96 -> Cleveland | P24: =IF(Pivot!B96="","",Pivot!B96) | Q24: =IF(Pivot!C96="","",Pivot!C96) | R24: =IF(Pivot!D96="","",Pivot!D96) | S24: =IF(Pivot!E96="","",Pivot!E96) | T24: =IF(Pivot!F96="","",Pivot!F96) | U24: =IF(Pivot!G96="","",Pivot!G96)
O25: =Pivot!A97 -> C0002 | P25: =IF(Pivot!B97="","",Pivot!B97) -> 1233 | Q25: =IF(Pivot!C97="","",Pivot!C97) -> 223 | R25: =IF(Pivot!D97="","",Pivot!D97) -> 1680 | S25: =IF(Pivot!E97="","",Pivot!E97) -> 990 | T25: =IF(Pivot!F97="","",Pivot!F97) -> 1508 | U25: =IF(Pivot!G97="","",Pivot!G97) -> 5634
O26: =Pivot!A98 -> C0007 | P26: =IF(Pivot!B98="","",Pivot!B98) -> 1598 | Q26: =IF(Pivot!C98="","",Pivot!C98) -> 1907 | R26: =IF(Pivot!D98="","",Pivot!D98) -> 869 | S26: =IF(Pivot!E98="","",Pivot!E98) -> 1426 | T26: =IF(Pivot!F98="","",Pivot!F98) -> 1416 | U26: =IF(Pivot!G98="","",Pivot!G98) -> 7216
O27: =Pivot!A99 -> C0008 | P27: =IF(Pivot!B99="","",Pivot!B99) -> 900 | Q27: =IF(Pivot!C99="","",Pivot!C99) -> 1016 | R27: =IF(Pivot!D99="","",Pivot!D99) -> 960 | S27: =IF(Pivot!E99="","",Pivot!E99) -> 940 | T27: =IF(Pivot!F99="","",Pivot!F99) -> 1193 | U27: =IF(Pivot!G99="","",Pivot!G99) -> 5009
M28: =Pivot!F49 -> % of calls:21% | O28: =Pivot!A100 -> C0010 | P28: =IF(Pivot!B100="","",Pivot!B100) -> 900 | Q28: =IF(Pivot!C100="","",Pivot!C100) -> 1470 | R28: =IF(Pivot!D100="","",Pivot!D100) -> 1617 | S28: =IF(Pivot!E100="","",Pivot!E100) -> 1314 | T28: =IF(Pivot!F100="","",Pivot!F100) -> 941 | U28: =IF(Pivot!G100="","",Pivot!G100) -> 6242
M29: =Pivot!F50 -> call rank:2 | O29: =Pivot!A101 -> C0013 | P29: =IF(Pivot!B101="","",Pivot!B101) -> 1255 | Q29: =IF(Pivot!C101="","",Pivot!C101) -> 516 | R29: =IF(Pivot!D101="","",Pivot!D101) -> 1874 | S29: =IF(Pivot!E101="","",Pivot!E101) -> 1863 | T29: =IF(Pivot!F101="","",Pivot!F101) -> 1722 | U29: =IF(Pivot!G101="","",Pivot!G101) -> 7230
M30: =Pivot!F51 -> amount rank:1 | O30: =Pivot!A102 -> C0015 | P30: =IF(Pivot!B102="","",Pivot!B102) -> 1138 | Q30: =IF(Pivot!C102="","",Pivot!C102) -> 1898 | R30: =IF(Pivot!D102="","",Pivot!D102) -> 1482 | S30: =IF(Pivot!E102="","",Pivot!E102) -> 846 | T30: =IF(Pivot!F102="","",Pivot!F102) -> 1154 | U30: =IF(Pivot!G102="","",Pivot!G102) -> 6518
O31: =Pivot!A103 -> Columbus | P31: =IF(Pivot!B103="","",Pivot!B103) | Q31: =IF(Pivot!C103="","",Pivot!C103) | R31: =IF(Pivot!D103="","",Pivot!D103) | S31: =IF(Pivot!E103="","",Pivot!E103) | T31: =IF(Pivot!F103="","",Pivot!F103) | U31: =IF(Pivot!G103="","",Pivot!G103)
O32: =Pivot!A104 -> C0001 | P32: =IF(Pivot!B104="","",Pivot!B104) -> 1655 | Q32: =IF(Pivot!C104="","",Pivot!C104) -> 805 | R32: =IF(Pivot!D104="","",Pivot!D104) -> 2263 | S32: =IF(Pivot!E104="","",Pivot!E104) -> 987 | T32: =IF(Pivot!F104="","",Pivot!F104) -> 1075 | U32: =IF(Pivot!G104="","",Pivot!G104) -> 6785
O33: =Pivot!A105 -> C0005 | P33: =IF(Pivot!B105="","",Pivot!B105) -> 1104 | Q33: =IF(Pivot!C105="","",Pivot!C105) -> 2280 | R33: =IF(Pivot!D105="","",Pivot!D105) -> 1445 | S33: =IF(Pivot!E105="","",Pivot!E105) -> 1722 | T33: =IF(Pivot!F105="","",Pivot!F105) -> 1196 | U33: =IF(Pivot!G105="","",Pivot!G105) -> 7747
O34: =Pivot!A106 -> C0006 | P34: =IF(Pivot!B106="","",Pivot!B106) -> 372 | Q34: =IF(Pivot!C106="","",Pivot!C106) -> 1818 | R34: =IF(Pivot!D106="","",Pivot!D106) -> 1346 | S34: =IF(Pivot!E106="","",Pivot!E106) -> 1156 | T34: =IF(Pivot!F106="","",Pivot!F106) -> 1484 | U34: =IF(Pivot!G106="","",Pivot!G106) -> 6176
O35: =Pivot!A107 -> C0009 | P35: =IF(Pivot!B107="","",Pivot!B107) -> 1415 | Q35: =IF(Pivot!C107="","",Pivot!C107) -> 1271 | R35: =IF(Pivot!D107="","",Pivot!D107) -> 1214 | S35: =IF(Pivot!E107="","",Pivot!E107) -> 1135 | T35: =IF(Pivot!F107="","",Pivot!F107) -> 1566 | U35: =IF(Pivot!G107="","",Pivot!G107) -> 6601
O36: =Pivot!A108 -> C0014 | P36: =IF(Pivot!B108="","",Pivot!B108) -> 1362 | Q36: =IF(Pivot!C108="","",Pivot!C108) -> 1363 | R36: =IF(Pivot!D108="","",Pivot!D108) -> 1152 | S36: =IF(Pivot!E108="","",Pivot!E108) -> 777 | T36: =IF(Pivot!F108="","",Pivot!F108) -> 750 | U36: =IF(Pivot!G108="","",Pivot!G108) -> 5404

Sheet Assets
